https://www.infobae.com/horoscopo: HTTP Error 404: Not Found <HTTPError 404: 'Not Found'> Traceback (most recent call last):
  File "c:\Develop\search_engine\scrapper\src\crawler.py", line 80, in crawl
    html = urlopen(url[1])
  File "C:\Users\mcerdeira\AppData\Local\Programs\Python\Python37-32\lib\urllib\request.py", line 222, in urlopen
    return opener.open(url, data, timeout)
  File "C:\Users\mcerdeira\AppData\Local\Programs\Python\Python37-32\lib\urllib\request.py", line 531, in open
    response = meth(req, response)
  File "C:\Users\mcerdeira\AppData\Local\Programs\Python\Python37-32\lib\urllib\request.py", line 641, in http_response
    'http', request, response, code, msg, hdrs)
  File "C:\Users\mcerdeira\AppData\Local\Programs\Python\Python37-32\lib\urllib\request.py", line 563, in error
    result = self._call_chain(*args)
  File "C:\Users\mcerdeira\AppData\Local\Programs\Python\Python37-32\lib\urllib\request.py", line 503, in _call_chain
    result = func(*args)
  File "C:\Users\mcerdeira\AppData\Local\Programs\Python\Python37-32\lib\urllib\request.py", line 755, in http_error_302
    return self.parent.open(new, timeout=req.timeout)
  File "C:\Users\mcerdeira\AppData\Local\Programs\Python\Python37-32\lib\urllib\request.py", line 531, in open
    response = meth(req, response)
  File "C:\Users\mcerdeira\AppData\Local\Programs\Python\Python37-32\lib\urllib\request.py", line 641, in http_response
    'http', request, response, code, msg, hdrs)
  File "C:\Users\mcerdeira\AppData\Local\Programs\Python\Python37-32\lib\urllib\request.py", line 569, in error
    return self._call_chain(*args)
  File "C:\Users\mcerdeira\AppData\Local\Programs\Python\Python37-32\lib\urllib\request.py", line 503, in _call_chain
    result = func(*args)
  File "C:\Users\mcerdeira\AppData\Local\Programs\Python\Python37-32\lib\urllib\request.py", line 649, in http_error_default
    raise HTTPError(req.full_url, code, msg, hdrs, fp)
urllib.error.HTTPError: HTTP Error 404: Not Found


---------------------------------------------https://www.infobae.com/cripto247/mercados/: HTTP Error 404: Not Found <HTTPError 404: 'Not Found'> Traceback (most recent call last):
  File "c:\Develop\search_engine\scrapper\src\crawler.py", line 80, in crawl
    html = urlopen(url[1])
  File "C:\Users\mcerdeira\AppData\Local\Programs\Python\Python37-32\lib\urllib\request.py", line 222, in urlopen
    return opener.open(url, data, timeout)
  File "C:\Users\mcerdeira\AppData\Local\Programs\Python\Python37-32\lib\urllib\request.py", line 531, in open
    response = meth(req, response)
  File "C:\Users\mcerdeira\AppData\Local\Programs\Python\Python37-32\lib\urllib\request.py", line 641, in http_response
    'http', request, response, code, msg, hdrs)
  File "C:\Users\mcerdeira\AppData\Local\Programs\Python\Python37-32\lib\urllib\request.py", line 569, in error
    return self._call_chain(*args)
  File "C:\Users\mcerdeira\AppData\Local\Programs\Python\Python37-32\lib\urllib\request.py", line 503, in _call_chain
    result = func(*args)
  File "C:\Users\mcerdeira\AppData\Local\Programs\Python\Python37-32\lib\urllib\request.py", line 649, in http_error_default
    raise HTTPError(req.full_url, code, msg, hdrs, fp)
urllib.error.HTTPError: HTTP Error 404: Not Found


---------------------------------------------https://www.infobae.com/turismo/rdm/: HTTP Error 404: Not Found <HTTPError 404: 'Not Found'> Traceback (most recent call last):
  File "c:\Develop\search_engine\scrapper\src\crawler.py", line 80, in crawl
    html = urlopen(url[1])
  File "C:\Users\mcerdeira\AppData\Local\Programs\Python\Python37-32\lib\urllib\request.py", line 222, in urlopen
    return opener.open(url, data, timeout)
  File "C:\Users\mcerdeira\AppData\Local\Programs\Python\Python37-32\lib\urllib\request.py", line 531, in open
    response = meth(req, response)
  File "C:\Users\mcerdeira\AppData\Local\Programs\Python\Python37-32\lib\urllib\request.py", line 641, in http_response
    'http', request, response, code, msg, hdrs)
  File "C:\Users\mcerdeira\AppData\Local\Programs\Python\Python37-32\lib\urllib\request.py", line 569, in error
    return self._call_chain(*args)
  File "C:\Users\mcerdeira\AppData\Local\Programs\Python\Python37-32\lib\urllib\request.py", line 503, in _call_chain
    result = func(*args)
  File "C:\Users\mcerdeira\AppData\Local\Programs\Python\Python37-32\lib\urllib\request.py", line 649, in http_error_default
    raise HTTPError(req.full_url, code, msg, hdrs, fp)
urllib.error.HTTPError: HTTP Error 404: Not Found


---------------------------------------------https://www.infobae.com/cripto247/bitcoin/: HTTP Error 404: Not Found <HTTPError 404: 'Not Found'> Traceback (most recent call last):
  File "c:\Develop\search_engine\scrapper\src\crawler.py", line 80, in crawl
    html = urlopen(url[1])
  File "C:\Users\mcerdeira\AppData\Local\Programs\Python\Python37-32\lib\urllib\request.py", line 222, in urlopen
    return opener.open(url, data, timeout)
  File "C:\Users\mcerdeira\AppData\Local\Programs\Python\Python37-32\lib\urllib\request.py", line 531, in open
    response = meth(req, response)
  File "C:\Users\mcerdeira\AppData\Local\Programs\Python\Python37-32\lib\urllib\request.py", line 641, in http_response
    'http', request, response, code, msg, hdrs)
  File "C:\Users\mcerdeira\AppData\Local\Programs\Python\Python37-32\lib\urllib\request.py", line 569, in error
    return self._call_chain(*args)
  File "C:\Users\mcerdeira\AppData\Local\Programs\Python\Python37-32\lib\urllib\request.py", line 503, in _call_chain
    result = func(*args)
  File "C:\Users\mcerdeira\AppData\Local\Programs\Python\Python37-32\lib\urllib\request.py", line 649, in http_error_default
    raise HTTPError(req.full_url, code, msg, hdrs, fp)
urllib.error.HTTPError: HTTP Error 404: Not Found


---------------------------------------------https://www.infobae.com/autor/víctor-salmerón/: 'ascii' codec can't encode character '\xed' in position 12: ordinal not in range(128) UnicodeEncodeError('ascii', 'GET /autor/víctor-salmerón/ HTTP/1.1', 12, 13, 'ordinal not in range(128)') Traceback (most recent call last):
  File "c:\Develop\search_engine\scrapper\src\crawler.py", line 80, in crawl
    html = urlopen(url[1])
  File "C:\Users\mcerdeira\AppData\Local\Programs\Python\Python37-32\lib\urllib\request.py", line 222, in urlopen
    return opener.open(url, data, timeout)
  File "C:\Users\mcerdeira\AppData\Local\Programs\Python\Python37-32\lib\urllib\request.py", line 525, in open
    response = self._open(req, data)
  File "C:\Users\mcerdeira\AppData\Local\Programs\Python\Python37-32\lib\urllib\request.py", line 543, in _open
    '_open', req)
  File "C:\Users\mcerdeira\AppData\Local\Programs\Python\Python37-32\lib\urllib\request.py", line 503, in _call_chain
    result = func(*args)
  File "C:\Users\mcerdeira\AppData\Local\Programs\Python\Python37-32\lib\urllib\request.py", line 1360, in https_open
    context=self._context, check_hostname=self._check_hostname)
  File "C:\Users\mcerdeira\AppData\Local\Programs\Python\Python37-32\lib\urllib\request.py", line 1317, in do_open
    encode_chunked=req.has_header('Transfer-encoding'))
  File "C:\Users\mcerdeira\AppData\Local\Programs\Python\Python37-32\lib\http\client.py", line 1229, in request
    self._send_request(method, url, body, headers, encode_chunked)
  File "C:\Users\mcerdeira\AppData\Local\Programs\Python\Python37-32\lib\http\client.py", line 1240, in _send_request
    self.putrequest(method, url, **skips)
  File "C:\Users\mcerdeira\AppData\Local\Programs\Python\Python37-32\lib\http\client.py", line 1107, in putrequest
    self._output(request.encode('ascii'))
UnicodeEncodeError: 'ascii' codec can't encode character '\xed' in position 12: ordinal not in range(128)


---------------------------------------------https://www.infobae.com/category/: HTTP Error 404: Not Found <HTTPError 404: 'Not Found'> Traceback (most recent call last):
  File "c:\Develop\search_engine\scrapper\src\crawler.py", line 80, in crawl
    html = urlopen(url[1])
  File "C:\Users\mcerdeira\AppData\Local\Programs\Python\Python37-32\lib\urllib\request.py", line 222, in urlopen
    return opener.open(url, data, timeout)
  File "C:\Users\mcerdeira\AppData\Local\Programs\Python\Python37-32\lib\urllib\request.py", line 531, in open
    response = meth(req, response)
  File "C:\Users\mcerdeira\AppData\Local\Programs\Python\Python37-32\lib\urllib\request.py", line 641, in http_response
    'http', request, response, code, msg, hdrs)
  File "C:\Users\mcerdeira\AppData\Local\Programs\Python\Python37-32\lib\urllib\request.py", line 569, in error
    return self._call_chain(*args)
  File "C:\Users\mcerdeira\AppData\Local\Programs\Python\Python37-32\lib\urllib\request.py", line 503, in _call_chain
    result = func(*args)
  File "C:\Users\mcerdeira\AppData\Local\Programs\Python\Python37-32\lib\urllib\request.py", line 649, in http_error_default
    raise HTTPError(req.full_url, code, msg, hdrs, fp)
urllib.error.HTTPError: HTTP Error 404: Not Found


